Workbook
Name IA: ENTREGAS!$A$4:$K$4

Sheet Asignaturas
A4: Código | B4: Sección | C4: Columna 1 | D4: Docentes | E4: Asignatura | G4: EVALUACIONES
A5: A1ADEE9 | B5: A | C5: =A5&B5 -> A1ADEE9A | D5: SUSSY DE LOS RIOS BOTTERI / | E5: EMPLOYEE EXPERIENCE | G5: Práctica 1
A6: A1AG1 | B6: A | C6: =A6&B6 -> A1AG1A | D6: ELSA MERCEDES ALAMA SALAZAR / | E6: FUNDAMENTOS DE ADMINISTRACIÓN 1 | G6: Práctica 2
A7: A1AG1 | B7: B | C7: =A7&B7 -> A1AG1B | D7: BEATRIZ ELVIRA VEGAS CHIYÓN / | E7: FUNDAMENTOS DE ADMINISTRACIÓN 1 | G7: Práctica 3
A8: A1AG1 | B8: C | C8: =A8&B8 -> A1AG1C | D8: BEATRIZ ELVIRA VEGAS CHIYÓN / | E8: FUNDAMENTOS DE ADMINISTRACIÓN 1 | G8: Práctica 4
A9: A1AG1 | B9: D | C9: =A9&B9 -> A1AG1D | D9: BEATRIZ ELVIRA VEGAS CHIYÓN / | E9: FUNDAMENTOS DE ADMINISTRACIÓN 1 | G9: Práctica 5
A10: A1AG2 | B10: A | C10: =A10&B10 -> A1AG2A | D10: CLAUDIA MARIA CHENG BARRANTES / | E10: FUNDAMENTOS DE ADMINISTRACIÓN 2 | G10: Parcial
A11: A1AG2 | B11: B | C11: =A11&B11 -> A1AG2B | D11: CLAUDIA MARIA CHENG BARRANTES / | E11: FUNDAMENTOS DE ADMINISTRACIÓN 2 | G11: Final
A12: A1AG3 | B12: A | C12: =A12&B12 -> A1AG3A | D12: FABIOLA ALCAS ROJAS / | E12: EMPRENDIMIENTO Y ESTRATEGIA | G12: Control 01
A13: A1AG3 | B13: B | C13: =A13&B13 -> A1AG3B | D13: FABIOLA ALCAS ROJAS / | E13: EMPRENDIMIENTO Y ESTRATEGIA | G13: Informe
A14: A1AG4 | B14: A | C14: =A14&B14 -> A1AG4A | D14: JUANA MARÍA HUACO GARCÍA / | E14: DISEÑO ORGANIZACIONAL | G14: Control 02
A15: A1AG4 | B15: B | C15: =A15&B15 -> A1AG4B | D15: JUANA MARÍA HUACO GARCÍA / | E15: DISEÑO ORGANIZACIONAL
A16: A1AG5 | B16: A | C16: =A16&B16 -> A1AG5A | D16: ELSA MERCEDES ALAMA SALAZAR / | E16: PSICOLOGÍA EN LAS ORGANIZACIONES | G16: Control 03
A17: A1AG5 | B17: B | C17: =A17&B17 -> A1AG5B | D17: ELSA MERCEDES ALAMA SALAZAR / | E17: PSICOLOGÍA EN LAS ORGANIZACIONES | G17: Control 04
A18: A1AG6 | B18: A | C18: =A18&B18 -> A1AG6A | D18: ALMA ROSA MACHUCA MAZA / | E18: DIRECCIÓN DE PERSONAL | G18: Control 05
A19: A1AG6 | B19: B | C19: =A19&B19 -> A1AG6B | D19: TEO ERNESTO MARTIN HIDALGO CORTES / | E19: DIRECCIÓN DE PERSONAL | G19: Control 06
A20: A1AGGE9 | B20: A | C20: =A20&B20 -> A1AGGE9A | D20: TEO ERNESTO MARTIN HIDALGO CORTES / | E20: GESTIÓN DE LA EMPLEABILIDAD | G20: Trabajo 01
A21: A1AGGI9 | B21: A | C21: =A21&B21 -> A1AGGI9A | D21: EDILBERTO LUIS PEDRO SALAZAR OSORES / | E21: GESTIÓN DE LA INNOVACIÓN | G21: Trabajo grupal
A22: A1AGIE9 | B22: A | C22: =A22&B22 -> A1AGIE9A | D22: CARLOS RODRICH / | E22: INNOVACIÓN EMPRESARIAL | G22: Participación
A23: A1BSA | B23: A | C23: =A23&B23 -> A1BSAA | D23: RICARDO ALBERTO ORMEÑO SÁNCHEZ / | E23: BUSINESS ANALYTICS | G23: Laboratorio
A24: A1BSA | B24: B | C24: =A24&B24 -> A1BSAB | D24: LUIS EGBERTO ALVARADO PINTADO / | E24: BUSINESS ANALYTICS | G24: Sustitutorio
A25: A1CC1 | B25: A | C25: =A25&B25 -> A1CC1A | D25: JORGE ARMANDO SANCHEZ FARFAN / | E25: CONTABILIDAD DE COSTOS | G25: REPROG P2
A26: A1CC1 | B26: B | C26: =A26&B26 -> A1CC1B | D26: YULLIANA MARISED LLAUCE ONTANEDA / | E26: CONTABILIDAD DE COSTOS | G26: REPROG P3
A27: A1CC2 | B27: A | C27: =A27&B27 -> A1CC2A | D27: SHIRLEY VANESSA TESEN SANDOVAL / | E27: COSTOS Y PRESUPUESTOS | G27: REPROG P4
... A47: A1ES2 | B47: A | C47: =A47&B47 -> A1ES2A | D47: LUIS EGBERTO ALVARADO PINTADO / | E47: ESTADÍSTICA 2 | G47: Trabajo grupal 1
A48: A1ES2 | B48: B | C48: =A48&B48 -> A1ES2B | D48: LUIS EGBERTO ALVARADO PINTADO / | E48: ESTADÍSTICA 2
A49: A1ETN | B49: A | C49: =A49&B49 -> A1ETNA | D49: MANUEL LÓPEZ ORTIZ / | E49: ÉTICA DE NEGOCIOS
A50: A1ETN | B50: B | C50: =A50&B50 -> A1ETNB | D50: MANUEL LÓPEZ ORTIZ / | E50: ÉTICA DE NEGOCIOS
A51: A1FP1 | B51: A | C51: =A51&B51 -> A1FP1A | D51: WILLIAN ALFREDO REYES CORTES / | E51: FUNDAMENTOS DE PROGRAMACIÓN
A52: A1FP1 | B52: B | C52: =A52&B52 -> A1FP1B | D52: WILLIAN ALFREDO REYES CORTES / | E52: FUNDAMENTOS DE PROGRAMACIÓN
A53: A1FP1 | B53: C | C53: =A53&B53 -> A1FP1C | D53: WILLIAN ALFREDO REYES CORTES / | E53: FUNDAMENTOS DE PROGRAMACIÓN
A54: A1FZ1 | B54: A | C54: =A54&B54 -> A1FZ1A | D54: JUAN RICARDO MATÍAS PALMA / | E54: METODOLOGÍA DE ESTUDIO
A55: A1FZ1 | B55: B | C55: =A55&B55 -> A1FZ1B | D55: JUAN RICARDO MATÍAS PALMA / | E55: METODOLOGÍA DE ESTUDIO
A56: A1FZ2 | B56: A | C56: =A56&B56 -> A1FZ2A | D56: RAFAEL ANTONIO VALERA MORENO / | E56: FINANZAS OPERATIVAS
A57: A1FZ2 | B57: B | C57: =A57&B57 -> A1FZ2B | D57: RAFAEL ANTONIO VALERA MORENO / | E57: FINANZAS OPERATIVAS
A58: A1FZ3 | B58: A | C58: =A58&B58 -> A1FZ3A | D58: JORGE EDUARDO GALLO COSTA / | E58: EVALUACIÓN DE INVERSIONES
A59: A1FZ3 | B59: B | C59: =A59&B59 -> A1FZ3B | D59: JORGE EDUARDO GALLO COSTA / | E59: EVALUACIÓN DE INVERSIONES
... A230: TE2 | B230: C | C230: =A230&B230 -> TE2C | D230: RICARDO GERMÁN GONZÁLEZ GATICA / | E230: TEOLOGÍA Y VIDA CRISTIANA
A231: MICR03002 | B231: A | C231: =A231&B231 -> MICR03002A | D231: GUSTAVO ALFREDO RIESCO LIND /
A232: MICR03002 | B232: A | C232: =A232&B232 -> MICR03002A | D232: GUSTAVO ALFREDO RIESCO LIND /
...

Sheet ENTREGAS
A2: EVALUACIONES POR RECOGER
L3: ingrese reclamos
A4: SIGLA | B4: SECC | C4: BUSCAR | D4: DOCENTE | E4: EVALUACIÓN | F4: TURNO | G4: DÍA DE ENTREGA | H4: VCTO. DEL RECLAMO | I4: HORA | J4: RECOJO | K4: LUGAR | L4: N° RECLAMOS | M4: OBS. | N4: Columna1
A5: A1MK2 | B5: A | C5: =A5&B5 -> A1MK2A | D5: =VLOOKUP($C5,Asignaturas!$C$5:$D$261,2,0) -> VICTOR ALEJANDRO DE LA TORRE PALACIOS / | E5: Práctica 1 | F5: AM | G5: 46121 | H5: 46122 | I5: 1:00p.m. | J5: =+Tabla2[[#This Row],[DÍA DE ENTREGA]]+8 -> 46129 | K5: CLASE | L5: 1
A6: A1CC1 | B6: A | C6: =A6&B6 -> A1CC1A | D6: =VLOOKUP($C6,Asignaturas!$C$5:$D$261,2,0) -> JORGE ARMANDO SANCHEZ FARFAN / | E6: Control 1 | F6: AM | G6: 46121 | H6: 46122 | I6: 1:00p.m. | J6: =+Tabla2[[#This Row],[DÍA DE ENTREGA]]+8 -> 46129 | K6: CLASE | L6: 1
A7: MACR03004 | B7: A | C7: =A7&B7 -> MACR03004A | D7: =VLOOKUP($C7,Asignaturas!$C$5:$D$261,2,0) -> ZENÓN FIDEL QUISPE MISAICO / | E7: Práctica 1 | F7: AM | G7: 46122 | H7: 46126 | I7: 1:00p.m. | J7: =+Tabla2[[#This Row],[DÍA DE ENTREGA]]+8 -> 46130 | K7: VENTANILLA | L7: 0
A8: A1EC1 | B8: A | C8: =A8&B8 -> A1EC1A | D8: =VLOOKUP($C8,Asignaturas!$C$5:$D$261,2,0) -> INGRID CECILIA CASANA ORTEGA / | E8: Práctica 1 | F8: AM | G8: 46122 | H8: 46126 | I8: 1:00p.m. | J8: =+Tabla2[[#This Row],[DÍA DE ENTREGA]]+8 -> 46130 | K8: CLASE | L8: 0
A9: A1EC1 | B9: B | C9: =A9&B9 -> A1EC1B | D9: =VLOOKUP($C9,Asignaturas!$C$5:$D$261,2,0) -> INGRID CECILIA CASANA ORTEGA / | E9: Práctica 1 | F9: AM | G9: 46121 | H9: 46122 | I9: 1:00p.m. | J9: =+Tabla2[[#This Row],[DÍA DE ENTREGA]]+8 -> 46129 | K9: CLASE | L9: 0
A10: MATE03008 | B10: B | C10: =A10&B10 -> MATE03008B | D10: =VLOOKUP($C10,Asignaturas!$C$5:$D$261,2,0) -> JAVIER FARFÁN NAVARRO / | E10: Control 1 | F10: AM | G10: 46120 | H10: 46121 | I10: 6:30p.m. | J10: =+Tabla2[[#This Row],[DÍA DE ENTREGA]]+8 -> 46128 | K10: CLASE | L10: 1 | M10: AÚN NO LLEGAN LOS SOBRANTES
A11: AF1 | B11: A | C11: =A11&B11 -> AF1A | D11: =VLOOKUP($C11,Asignaturas!$C$5:$D$261,2,0) -> CLAUDIA MARÍA RIVERA TÁVARA / | E11: Control 1 | F11: PM | G11: 46122 | H11: 46126 | I11: 6:30p.m. | J11: =+Tabla2[[#This Row],[DÍA DE ENTREGA]]+8 -> 46130 | K11: CLASE
A12: CF4 | B12: A | C12: =A12&B12 -> CF4A | D12: =VLOOKUP($C12,Asignaturas!$C$5:$D$261,2,0) -> MARÍA CECILIA VENEGAS MORALES / | E12: Práctica 1 | F12: AM | G12: 46126 | H12: 46127 | I12: 1:00p.m. | J12: =+Tabla2[[#This Row],[DÍA DE ENTREGA]]+8 -> 46134 | K12: VENTANILLA | L12: 0
A13: HC1 | B13: C | C13: =A13&B13 -> HC1C | D13: =VLOOKUP($C13,Asignaturas!$C$5:$D$261,2,0) -> ADRIANA ISABEL LAOS LEVAGGI / | E13: Práctica 1 | F13: PM | G13: 46126 | H13: 46127 | I13: 6:30p.m. | J13: =+Tabla2[[#This Row],[DÍA DE ENTREGA]]+8 -> 46134 | K13: VENTANILLA | L13: 2
A14: ESTA03008 | B14: A | C14: =A14&B14 -> ESTA03008A | D14: =VLOOKUP($C14,Asignaturas!$C$5:$D$261,2,0) -> CRISTIAN ADDERLY MARAVI MENESES / | E14: Práctica 1 | F14: AM | G14: 46126 | H14: 46127 | I14: 1:00p.m. | J14: =+Tabla2[[#This Row],[DÍA DE ENTREGA]]+8 -> 46134 | K14: CLASE | L14: 2
A15: A1DPRT9 | B15: A | C15: =A15&B15 -> A1DPRT9A | D15: =VLOOKUP($C15,Asignaturas!$C$5:$D$261,2,0) -> MANUEL PRENDES GUARDIOLA / | E15: Práctica 1 | F15: PM | G15: 46126 | H15: 46127 | I15: 6:30p.m. | J15: =+Tabla2[[#This Row],[DÍA DE ENTREGA]]+8 -> 46134 | K15: CLASE | L15: 1
A16: FINZ03032 | B16: A | C16: =A16&B16 -> FINZ03032A | D16: =VLOOKUP($C16,Asignaturas!$C$5:$D$261,2,0) -> BRENDA SILUPÚ GARCÉS / SERGIO DAVID REYES LANDA / | E16: Práctica 1 | F16: AM | G16: 46127 | H16: 46128 | I16: 1:00p.m. | J16: =+Tabla2[[#This Row],[DÍA DE ENTREGA]]+8 -> 46135 | K16: CLASE | L16: 0
A17: MATE03008 | B17: A | C17: =A17&B17 -> MATE03008A | D17: =VLOOKUP($C17,Asignaturas!$C$5:$D$261,2,0) -> JAVIER FARFÁN NAVARRO / | E17: Práctica 1 | F17: AM | G17: 46127 | H17: 46128 | I17: 1:00p.m. | J17: =+Tabla2[[#This Row],[DÍA DE ENTREGA]]+8 -> 46135 | K17: CLASE | L17: 6
A18: MATE03008 | B18: C | C18: =A18&B18 -> MATE03008C | D18: =VLOOKUP($C18,Asignaturas!$C$5:$D$261,2,0) -> JAVIER FARFÁN NAVARRO / | E18: Práctica 1 | F18: AM | G18: 46127 | H18: 46128 | I18: 1:00p.m. | J18: =+Tabla2[[#This Row],[DÍA DE ENTREGA]]+8 -> 46135 | K18: CLASE | L18: 7
A19: MATE03009 | B19: A | C19: =A19&B19 -> MATE03009A | D19: =VLOOKUP($C19,Asignaturas!$C$5:$D$261,2,0) -> NESTOR FARÍAS / WILLIAN REYES | E19: Práctica 1 | F19: AM | G19: 46127 | H19: 46128 | I19: 1:00p.m. | J19: =+Tabla2[[#This Row],[DÍA DE ENTREGA]]+8 -> 46135 | K19: CLASE | L19: 5
A20: MACR03002 | B20: A | C20: =A20&B20 -> MACR03002A | D20: =VLOOKUP($C20,Asignaturas!$C$5:$D$261,2,0) -> LUIS ALONSO CASAVERDE ANTÓN / | E20: Práctica 1 | F20: AM | G20: 46128 | H20: 46129 | I20: 1:00p.m. | J20: =+Tabla2[[#This Row],[DÍA DE ENTREGA]]+8 -> 46136 | K20: CLASE | L20: 1
A21: A1CF2 | B21: B | C21: =A21&B21 -> A1CF2B | D21: =VLOOKUP($C21,Asignaturas!$C$5:$D$261,2,0) -> MARLON RAUL ALVIA SIANCAS / | E21: Control 01 | F21: AM | G21: 46128 | H21: 46129 | I21: 1:00p.m. | J21: =+Tabla2[[#This Row],[DÍA DE ENTREGA]]+8 -> 46136 | K21: CLASE | L21: 0
A22: GTH | B22: A | C22: =A22&B22 -> GTHA | D22: =VLOOKUP($C22,Asignaturas!$C$5:$D$261,2,0) -> JUANA MARÍA HUACO GARCÍA / TEO ERNESTO MARTIN HIDALGO CORTES / | E22: Práctica 1 | F22: AM | G22: 46129 | H22: 46132 | I22: 1:00p.m. | J22: =+Tabla2[[#This Row],[DÍA DE ENTREGA]]+8 -> 46137 | K22: VENTANILLA | L22: 0
A23: HC1 | B23: F | C23: =A23&B23 -> HC1F | D23: =VLOOKUP($C23,Asignaturas!$C$5:$D$261,2,0) -> JAVIER GOMEZ SANCHEZ / | E23: Práctica 1 | F23: AM | G23: 46128 | H23: 46129 | I23: 1:00p.m. | J23: =+Tabla2[[#This Row],[DÍA DE ENTREGA]]+8 -> 46136 | K23: CLASE | L23: 0
... A53: CF5 | B53: A | C53: =A53&B53 -> CF5A | D53: =VLOOKUP($C53,Asignaturas!$C$5:$D$261,2,0) -> MARÍA JESUS FARFÁN / IVETTE NUÑEZ LAGUNA | E53: Práctica 1 | F53: AM | G53: 46132 | H53: 46133 | I53: 1:00p.m. | J53: =+Tabla2[[#This Row],[DÍA DE ENTREGA]]+8 -> 46140 | K53: CLASE | L53: 0
A54: A1FZ1 | B54: A | C54: =A54&B54 -> A1FZ1A | D54: =VLOOKUP($C54,Asignaturas!$C$5:$D$261,2,0) -> JUAN RICARDO MATÍAS PALMA / | E54: Práctica 1 | F54: AM | G54: 46133 | H54: 46134 | I54: 1:00p.m. | J54: =+Tabla2[[#This Row],[DÍA DE ENTREGA]]+8 -> 46141 | K54: CLASE | L54: 3 | M54: AÚN NO LLEGAN LOS SOBRANTES
A55: MICR03005 | B55: A | C55: =A55&B55 -> MICR03005A | D55: =VLOOKUP($C55,Asignaturas!$C$5:$D$261,2,0) -> ALFONSO GUILLERMO DULANTO RISHING / | E55: Práctica 1 | F55: AM | G55: 46130 | H55: 46133 | I55: 1:00p.m. | J55: =+Tabla2[[#This Row],[DÍA DE ENTREGA]]+8 -> 46138 | K55: CLASE | L55: 6 | M55: AÚN NO LLEGAN LOS SOBRANTES
A56: M4DS | B56: A | C56: =A56&B56 -> M4DSA | D56: =VLOOKUP($C56,Asignaturas!$C$5:$D$261,2,0) -> LOURDES RENATA CORONADO GOMEZ / | E56: Taller 01 | F56: AM | G56: 46135 | H56: 46136 | I56: 1:00p.m. | J56: =+Tabla2[[#This Row],[DÍA DE ENTREGA]]+11 -> 46146 | K56: VENTANILLA | L56: 0
A57: A1CC1 | B57: A | C57: =A57&B57 -> A1CC1A | D57: =VLOOKUP($C57,Asignaturas!$C$5:$D$261,2,0) -> JORGE ARMANDO SANCHEZ FARFAN / | E57: Control 02 | F57: AM | G57: 46135 | H57: 46136 | I57: 1:00p.m. | J57: =+Tabla2[[#This Row],[DÍA DE ENTREGA]]+11 -> 46146 | K57: CLASE | L57: 0
A58: A1MK1 | B58: A | C58: =A58&B58 -> A1MK1A | D58: =VLOOKUP($C58,Asignaturas!$C$5:$D$261,2,0) -> GONZALO GUILLERMO AUGUSTO VOYSEST / | E58: Práctica 1 | F58: AM | G58: 46132 | H58: 46133 | I58: 1:00p.m. | J58: =+Tabla2[[#This Row],[DÍA DE ENTREGA]]+8 -> 46140 | K58: CLASE | L58: 0
A59: AF1 | B59: A | C59: =A59&B59 -> AF1A | D59: =VLOOKUP($C59,Asignaturas!$C$5:$D$261,2,0) -> CLAUDIA MARÍA RIVERA TÁVARA / | E59: Práctica 1 | F59: PM | G59: 46134 | H59: 46135 | I59: 6:30p.m. | J59: =+Tabla2[[#This Row],[DÍA DE ENTREGA]]+8 -> 46142 | K59: CLASE | L59: 0
A60: A1MK3 | B60: B | C60: =A60&B60 -> A1MK3B | D60: =VLOOKUP($C60,Asignaturas!$C$5:$D$261,2,0) -> ANA LUCÍA MARTÍNEZ AZCÁRATE / | E60: Controles | F60: AM | G60: 46135 | H60: 46136 | I60: 1:00p.m. | J60: =+Tabla2[[#This Row],[DÍA DE ENTREGA]]+11 -> 46146 | K60: VENTANILLA | L60: 0
A61: A1FZ2 | B61: A | C61: =A61&B61 -> A1FZ2A | D61: =VLOOKUP($C61,Asignaturas!$C$5:$D$261,2,0) -> RAFAEL ANTONIO VALERA MORENO / | E61: Práctica 1 | F61: AM | G61: 46135 | H61: 46136 | I61: 1:00p.m. | J61: =+Tabla2[[#This Row],[DÍA DE ENTREGA]]+11 -> 46146 | K61: VENTANILLA | L61: 1
A62: A1FZ2 | B62: B | C62: =A62&B62 -> A1FZ2B | D62: =VLOOKUP($C62,Asignaturas!$C$5:$D$261,2,0) -> RAFAEL ANTONIO VALERA MORENO / | E62: Práctica 1 | F62: AM | G62: 46135 | H62: 46136 | I62: 1:00p.m. | J62: =+Tabla2[[#This Row],[DÍA DE ENTREGA]]+11 -> 46146 | K62: VENTANILLA | L62: 1
A63: HC3 | B63: A | C63: =A63&B63 -> HC3A | D63: =VLOOKUP($C63,Asignaturas!$C$5:$D$261,2,0) -> JAVIER GOMEZ SANCHEZ / | E63: Práctica 1 | F63: AM | G63: 46134 | H63: 46135 | I63: 1:00p.m. | J63: =+Tabla2[[#This Row],[DÍA DE ENTREGA]]+8 -> 46142 | K63: CLASE | L63: 0
A64: RCO | B64: A | C64: =A64&B64 -> RCOA | D64: =VLOOKUP($C64,Asignaturas!$C$5:$D$261,2,0) -> FERNANDO ALFREDO RIOFRIO ZUÑIGA / | E64: Práctica 1 | F64: PM | G64: 46135 | H64: 46136 | I64: 6:30p.m. | J64: =+Tabla2[[#This Row],[DÍA DE ENTREGA]]+11 -> 46146 | K64: VENTANILLA | L64: 1
A65: RCO | B65: C | C65: =A65&B65 -> RCOC | D65: =VLOOKUP($C65,Asignaturas!$C$5:$D$261,2,0) -> FERNANDO ALFREDO RIOFRIO ZUÑIGA / | E65: Práctica 1 | F65: PM | G65: 46135 | H65: 46136 | I65: 6:30p.m. | J65: =+Tabla2[[#This Row],[DÍA DE ENTREGA]]+11 -> 46146 | K65: VENTANILLA | L65: 0
A66: A1CF1 | B66: B | C66: =A66&B66 -> A1CF1B | D66: =VLOOKUP($C66,Asignaturas!$C$5:$D$261,2,0) -> MARIA JESÚS FARFÁN MANRIQUE / | E66: Práctica 1 | F66: AM | G66: 46135 | H66: 46136 | I66: 1:00p.m. | J66: =+Tabla2[[#This Row],[DÍA DE ENTREGA]]+8 -> 46143 | K66: CLASE | L66: 2
A67: A1FZ1 | B67: B | C67: =A67&B67 -> A1FZ1B | D67: =VLOOKUP($C67,Asignaturas!$C$5:$D$261,2,0) -> JUAN RICARDO MATÍAS PALMA / | E67: Práctica 1 | F67: PM | G67: 46132 | H67: 46133 | I67: 6:30p.m. | J67: =+Tabla2[[#This Row],[DÍA DE ENTREGA]]+8 -> 46140 | K67: CLASE | L67: 0
A68: GTH | B68: A | C68: =A68&B68 -> GTHA | D68: =VLOOKUP($C68,Asignaturas!$C$5:$D$261,2,0) -> JUANA MARÍA HUACO GARCÍA / TEO ERNESTO MARTIN HIDALGO CORTES / | E68: Práctica 2 | F68: AM | G68: 46136 | H68: 46139 | I68: 1:00p.m. | J68: =+Tabla2[[#This Row],[DÍA DE ENTREGA]]+8 -> 46144 | K68: VENTANILLA | L68: 0
A69: HC3 | B69: C | C69: =A69&B69 -> HC3C | D69: =VLOOKUP($C69,Asignaturas!$C$5:$D$261,2,0) -> ADRIANA ISABEL LAOS LEVAGGI / | E69: Práctica 1 | F69: AM | G69: 46136 | H69: 46139 | I69: 1:00p.m. | J69: =+Tabla2[[#This Row],[DÍA DE ENTREGA]]+8 -> 46144 | K69: CLASE | L69: =2+3 -> 5
A70: A1FZ4 | B70: A | C70: =A70&B70 -> A1FZ4A | D70: =VLOOKUP($C70,Asignaturas!$C$5:$D$261,2,0) -> ALVARO TRESIERRA / SERGIO REYES | E70: Práctica 1 | F70: PM | G70: 46135 | H70: 46136 | I70: 6:30p.m. | J70: =+Tabla2[[#This Row],[DÍA DE ENTREGA]]+8 -> 46143 | K70: CLASE | L70: 0
...

Sheet RECLAMOS
A2: RECLAMOS POR RECOGER
A4: SIGLA | B4: SECC | C4: BUSCAR | D4: DOCENTE | E4: EVALUACIÓN | F4: TURNO | G4: DÍA DE ENTREGA | H4: VENCIMIENTO PARA 2° RECLAMO | I4: HORA | J4: CANTIDAD 2°RECLAMOS | K4: OBSERVACIÓN
A5: A1MK2 | B5: A | C5: =A5&B5 -> A1MK2A | D5: =VLOOKUP($C5,Asignaturas!$C$5:$D$261,2,0) -> VICTOR ALEJANDRO DE LA TORRE PALACIOS / | E5: Control 01 | F5: AM | G5: 46128 | H5: 46129 | I5: 1:00 p.m.
A6: A1DPRT9 | B6: A | C6: =A6&B6 -> A1DPRT9A | D6: =VLOOKUP($C6,Asignaturas!$C$5:$D$261,2,0) -> MANUEL PRENDES GUARDIOLA / | E6: Práctica 1 | F6: AM | G6: 46134 | H6: 46135 | I6: 1:00 p.m.
A7: MATE03009 | B7: A | C7: =A7&B7 -> MATE03009A | D7: =VLOOKUP($C7,Asignaturas!$C$5:$D$261,2,0) -> NESTOR FARÍAS / WILLIAN REYES | E7: Práctica 1 | F7: AM | G7: 46134 | H7: 46135 | I7: 1:00 p.m.
A8: A1FZ3 | B8: A | C8: =A8&B8 -> A1FZ3A | D8: =VLOOKUP($C8,Asignaturas!$C$5:$D$261,2,0) -> JORGE EDUARDO GALLO COSTA / | E8: Práctica 1 | F8: AM | G8: 46135 | H8: 46135 | I8: 1:00 p.m.
A9: A1CC1 | B9: A | C9: =A9&B9 -> A1CC1A | D9: =VLOOKUP($C9,Asignaturas!$C$5:$D$261,2,0) -> JORGE ARMANDO SANCHEZ FARFAN / | E9: Control 01 | F9: AM | G9: 46135 | H9: 46135 | I9: 1:00 p.m.
A10: MATE03010 | B10: A | C10: =A10&B10 -> MATE03010A | D10: =VLOOKUP($C10,Asignaturas!$C$5:$D$261,2,0) -> RANDY JOEL FERNÁNDEZ PALOMINO / | E10: Práctica 1 | F10: AM | G10: 46135 | H10: 46135 | I10: 1:00 p.m.
A11: MATE03008 | B11: B | C11: =A11&B11 -> MATE03008B | D11: =VLOOKUP($C11,Asignaturas!$C$5:$D$261,2,0) -> JAVIER FARFÁN NAVARRO / | E11: Práctica 1 | F11: PM | G11: 46135 | H11: 46135 | I11: 6:00 p.m.
A12: MATE03008 | B12: C | C12: =A12&B12 -> MATE03008C | D12: =VLOOKUP($C12,Asignaturas!$C$5:$D$261,2,0) -> JAVIER FARFÁN NAVARRO / | E12: Práctica 1 | F12: PM | G12: 46135 | H12: 46135 | I12: 6:00 p.m.
A13: HC1 | B13: C | C13: =A13&B13 -> HC1C | D13: =VLOOKUP($C13,Asignaturas!$C$5:$D$261,2,0) -> ADRIANA ISABEL LAOS LEVAGGI / | E13: Práctica 1 | F13: AM | G13: 46136 | H13: 46139 | I13: 1:00 p.m.
A14: MATE03008 | B14: A | C14: =A14&B14 -> MATE03008A | D14: =VLOOKUP($C14,Asignaturas!$C$5:$D$261,2,0) -> JAVIER FARFÁN NAVARRO / | E14: Práctica 1 | F14: AM | G14: 46140 | H14: 46141 | I14: 1:00 p.m.
A15: A1FZ1 | B15: A | C15: =A15&B15 -> A1FZ1A | D15: =VLOOKUP($C15,Asignaturas!$C$5:$D$261,2,0) -> JUAN RICARDO MATÍAS PALMA / | E15: Práctica 1 | F15: AM | G15: 46140 | H15: 46141 | I15: 1:00 p.m.
A16: MATE03007 | B16: A | C16: =A16&B16 -> MATE03007A | D16: =VLOOKUP($C16,Asignaturas!$C$5:$D$261,2,0) -> CARLOS IMÁN ANCAJIMA / | E16: Práctica 1 | F16: AM | G16: 46140 | H16: 46141 | I16: 1:00 p.m.
... A51: HC1 | B51: C | C51: =A51&B51 -> HC1C | D51: =VLOOKUP($C51,Asignaturas!$C$5:$D$261,2,0) -> ADRIANA ISABEL LAOS LEVAGGI / | E51: Práctica 2 | F51: PM | G51: 46150 | H51: 46153 | I51: 6:00 p.m.
C52: =A52&B52 | D52: =VLOOKUP($C52,Asignaturas!$C$5:$D$261,2,0) -> 0
C53: =A53&B53 | D53: =VLOOKUP($C53,Asignaturas!$C$5:$D$261,2,0) -> 0
C54: =A54&B54 | D54: =VLOOKUP($C54,Asignaturas!$C$5:$D$261,2,0) -> 0
C55: =A55&B55 | D55: =VLOOKUP($C55,Asignaturas!$C$5:$D$261,2,0) -> 0
C56: =A56&B56 | D56: =VLOOKUP($C56,Asignaturas!$C$5:$D$261,2,0) -> 0
C57: =A57&B57 | D57: =VLOOKUP($C57,Asignaturas!$C$5:$D$261,2,0) -> 0
C58: =A58&B58 | D58: =VLOOKUP($C58,Asignaturas!$C$5:$D$261,2,0) -> 0
C59: =A59&B59 | D59: =VLOOKUP($C59,Asignaturas!$C$5:$D$261,2,0) -> 0
C60: =A60&B60 | D60: =VLOOKUP($C60,Asignaturas!$C$5:$D$261,2,0) -> 0
C61: =A61&B61 | D61: =VLOOKUP($C61,Asignaturas!$C$5:$D$261,2,0) -> 0
C62: =A62&B62 | D62: =VLOOKUP($C62,Asignaturas!$C$5:$D$261,2,0) -> 0
C63: =A63&B63 | D63: =VLOOKUP($C63,Asignaturas!$C$5:$D$261,2,0) -> 0
... C185: =A185&B185 | D185: =VLOOKUP($C185,Asignaturas!$C$5:$D$261,2,0) -> 0
C186: =A186&B186 | D186: =VLOOKUP($C186,Asignaturas!$C$5:$D$261,2,0) -> 0 | F186: AM | G186: 45982 | H186: 45985 | I186: 1:00 p.m.
C187: =A187&B187 | D187: =VLOOKUP($C187,Asignaturas!$C$5:$D$261,2,0) -> 0 | E187: PC3 | F187: PM | G187: 45982 | H187: 45985 | I187: 6:00 p.m.
C188: =A188&B188 | D188: =VLOOKUP($C188,Asignaturas!$C$5:$D$261,2,0) -> 0 | E188: PC3 | F188: AM | G188: 45985 | H188: 45986 | I188: 1:00 p.m.
C189: =A189&B189 | D189: =VLOOKUP($C189,Asignaturas!$C$5:$D$261,2,0) -> 0 | E189: PC3 | F189: AM | G189: 45985 | H189: 45986 | I189: 1:00 p.m.
C190: =A190&B190 | D190: =VLOOKUP($C190,Asignaturas!$C$5:$D$261,2,0) -> 0 | E190: PC3 | F190: AM | G190: 45985 | H190: 45986 | I190: 1:00 p.m.
C191: =A191&B191 | D191: =VLOOKUP($C191,Asignaturas!$C$5:$D$261,2,0) -> 0 | E191: PC4 | F191: AM | G191: 45985 | H191: 45986 | I191: 1:00 p.m.
C192: =A192&B192 | D192: =VLOOKUP($C192,Asignaturas!$C$5:$D$261,2,0) -> 0 | E192: PC3 | F192: PM | G192: 45985 | H192: 45986 | I192: 6:00 p.m.
C193: =A193&B193 | D193: =VLOOKUP($C193,Asignaturas!$C$5:$D$261,2,0) -> 0 | E193: PC3 | F193: PM | G193: 45985 | H193: 45986 | I193: 6:00 p.m.
C194: =A194&B194 | D194: =VLOOKUP($C194,Asignaturas!$C$5:$D$261,2,0) -> 0 | E194: PC3 | F194: PM | G194: 45985 | H194: 45986 | I194: 6:00 p.m.
C195: =A195&B195 | D195: =VLOOKUP($C195,Asignaturas!$C$5:$D$261,2,0) -> 0 | E195: PC2 | F195: AM | G195: 45986 | H195: 45987 | I195: 1:00 p.m.
C196: =A196&B196 | D196: =VLOOKUP($C196,Asignaturas!$C$5:$D$261,2,0) -> 0 | E196: PC2 | F196: AM | G196: 45986 | H196: 45987 | I196: 1:00 p.m.
C197: =A197&B197 | D197: =VLOOKUP($C197,Asignaturas!$C$5:$D$261,2,0) -> 0 | E197: PC3 | F197: PM | G197: 45986 | H197: 45987 | I197: 6:00 p.m.
...

Sheet CONTRAreclamos
A2: CONTROL DE SEGUNDOS RECLAMOS 2025-I
A4: SIGLA | B4: APELLIDOS Y NOMBRES | C4: SECCIÓN | D4: BUSCAR | E4: PROFESOR de la asignatura | F4: EVALUACIÓN | G4: DIA DE ENTREGA por el alumno | H4: PROFESOR QUE CORREJIRÁ | I4: FECHA de recepción por quien corrije | J4: RESUELTO(CAMBIA NOTA) | K4: NP/P
D5: =A5&C5 | E5: =VLOOKUP(D5,Asignaturas!$C$5:$D$261,2,0) -> 0
D6: =A6&C6 | E6: =VLOOKUP(D6,Asignaturas!$C$5:$D$261,2,0) -> 0
D7: =A7&C7 | E7: =VLOOKUP(D7,Asignaturas!$C$5:$D$261,2,0) -> 0
D8: =A8&C8 | E8: =VLOOKUP(D8,Asignaturas!$C$5:$D$261,2,0) -> 0
D9: =A9&C9 | E9: =VLOOKUP(D9,Asignaturas!$C$5:$D$261,2,0) -> 0
D10: =A10&C10 | E10: =VLOOKUP(D10,Asignaturas!$C$5:$D$261,2,0) -> 0
D11: =A11&C11 | E11: =VLOOKUP(D11,Asignaturas!$C$5:$D$261,2,0) -> 0
D12: =A12&C12 | E12: =VLOOKUP(D12,Asignaturas!$C$5:$D$261,2,0) -> 0
D13: =A13&C13 | E13: =VLOOKUP(D13,Asignaturas!$C$5:$D$261,2,0) -> 0
D14: =A14&C14 | E14: =VLOOKUP(D14,Asignaturas!$C$5:$D$261,2,0) -> 0
D15: =A15&C15 | E15: =VLOOKUP(D15,Asignaturas!$C$5:$D$261,2,0) -> 0
D16: =A16&C16 | E16: =VLOOKUP(D16,Asignaturas!$C$5:$D$261,2,0) -> 0
... D54: =A54&C54 | E54: =VLOOKUP(D54,Asignaturas!$C$5:$D$261,2,0) -> 0
E55: =VLOOKUP(D55,Asignaturas!$C$5:$D$261,2,0) -> #N/A
E56: =VLOOKUP(D56,Asignaturas!$C$5:$D$261,2,0) -> #N/A
E57: =VLOOKUP(D57,Asignaturas!$C$5:$D$261,2,0) -> #N/A
E58: =VLOOKUP(D58,Asignaturas!$C$5:$D$261,2,0) -> #N/A
